<robot name="mycar" xmlns:xacro="http://www.ros.org/wiki/xacro">
    <!-- link属性 -->
    <xacro:property name="link4_radius" value="0.1" />
    <xacro:property name="link4_height" value="0.4" />
    <xacro:property name="link4_m" value="0.3" />
    <xacro:property name="distance34" value="-0.04" /> <!-- 质量  -->
    <link name="link4">
      <visual>
        <geometry>
          <mesh filename="package://demo02_urdf_gazebo/stl/link_4.STL"/>
        </geometry>
        <origin xyz="0 0 0.01" rpy="${PI/2} 0 0" />
        <material name="yellow">
          <color rgba="0.5 0.3 0.0 0.5" />
        </material>
      </visual>
      <collision>
        <geometry>
          <mesh filename="package://demo02_urdf_gazebo/stl/link_4.STL"/>
        </geometry>
        <origin xyz="0 0 0.01" rpy="${PI/2} 0 0" />
      </collision>
      <inertial>
        <origin xyz="0 0 0.196" />
        <mass value="0.649" />
        <inertia ixx="10.300" ixy="0" ixz="0" iyy="10.300" iyz="0" izz="0.192" />
        <!--<inertia ixx="0.010300" ixy="0" ixz="0" iyy="0.010300" iyz="0" izz="0.000012" />-->
      </inertial>

    </link>

    <joint name="joint4" type="continuous">
      <parent link="link3" />
      <child link="link4"/>
      <origin xyz="0 0.1 -0.04" rpy = "${PI/-2} ${PI} 0"/>
      <axis xyz="0 0 1" />
    </joint>
    
    <gazebo reference="link4">
        <material>Gazebo/Yellow</material>
    </gazebo>

</robot>
