<robot name="mycar" xmlns:xacro="http://www.ros.org/wiki/xacro">
    <!-- link属性 -->
    <xacro:property name="link3_radius" value="0.2" />
    <xacro:property name="link3_height" value="0.2" />
    <xacro:property name="link3_m" value="0.3" />
    <xacro:property name="distance23" value="-0.3" /> <!-- 质量  -->
    <link name="link3">
      <visual>
        <geometry>
          <mesh filename="package://demo02_urdf_gazebo/stl/link_3.STL"/>
        </geometry>
        <origin xyz="0 0 0" rpy="${PI/2} ${PI/-2} 0" />
        <material name="yellow">
          <color rgba="0.5 0.3 0.0 0.5" />
        </material>
      </visual>
      <collision>
        <geometry>
          <mesh filename="package://demo02_urdf_gazebo/stl/link_3.STL"/>
        </geometry>
        <origin xyz="0 0 0" rpy="${PI/2} ${PI/-2} 0" />
      </collision>
      <inertial>
        <origin xyz="0.012 0.036 -0.054" />
        <mass value="1.238" />
        <inertia ixx="4.115" ixy="0.101" ixz="-0.349" iyy="3.405" iyz="-0.238" izz="4.223" />
        <!--<inertia ixx="0.004115" ixy="0" ixz="0" iyy="0.003405" iyz="0" izz="0.004223" />-->
      </inertial>

    </link>

    <joint name="joint3" type="continuous">
      <parent link="link2" />
      <child link="link3"/>
      <origin xyz="0 -0.4 0.04" rpy = "0 0 ${PI/-2}"/>
      <axis xyz="0 0 1" />
    </joint>
    <gazebo reference="link3">
        <material>Gazebo/Red</material>
    </gazebo>

</robot>
