<robot name="mycar" xmlns:xacro="http://www.ros.org/wiki/xacro">
    <!-- link属性 -->
    <xacro:property name="link5_radius" value="0.1" />
    <xacro:property name="link5_height" value="0.2" />
    <xacro:property name="link5_m" value="0.2" />
    <xacro:property name="distance45" value="-0.3" /> <!-- 质量  -->
    <link name="link5">
      <visual>
        <geometry>
          <mesh filename="package://demo02_urdf_gazebo/stl/link_5.STL"/>
        </geometry>
        <origin xyz="0 0 0" rpy="${PI/-2} ${PI/-2} 0" />
        <material name="yellow">
          <color rgba="0.5 0.3 0.0 0.5" />
        </material>
      </visual>
      <collision>
        <geometry>
          <mesh filename="package://demo02_urdf_gazebo/stl/link_5.STL"/>
        </geometry>
        <origin xyz="0 0 0" rpy="${PI/-2} ${PI/-2} 0" />
      </collision>
      <inertial>
        <origin xyz="-0.012 0 0.018" />
        <mass value="0.744" />
        <inertia ixx="1.479" ixy="0" ixz="0.136" iyy="4.669" iyz="0" izz="3.975" />
        <!--<inertia ixx="0.001479" ixy="0" ixz="0" iyy="0.004669" iyz="0" izz="0.003975" />-->
      </inertial>

    </link>

    <joint name="joint5" type="continuous">
      <parent link="link4" />
      <child link="link5"/>
      <origin xyz="0 0 ${link4_height}" rpy = "${PI/-2} ${PI} 0"/>
      <axis xyz="0 0 1" />
    </joint>
    
    <gazebo reference="link5">
        <material>Gazebo/Blue</material>
    </gazebo>

</robot>
